Workbook
Name Space_air_rates: '[1]Table 6-1 Rates'!$A$5:$F$84
Name Space_index: #REF!

Sheet Table 6-1 Rates
A2: Standard 62.1 Outdoor Air Rates (Table 6-1) | J2: OVERRIDDEN
B3: IP | D3: SI | F3: Default Occupant Density | G3: T24 Occ Minimum | H3: T24 DCV Minimum | I3: T24 DCV/Occ Standby
A4: Occupancy Category | B4: Rp (cfm/per) | C4: Ra (cfm/ft2) | D4: Rp (L/s-per) | E4: Ra (L/s-m2) | F4: #/1000 ft2 (#/100 m2) | G4: T24 Occ Minimum CFM/sqft | H4: T24 DCV Minimum CFM/sqft | I4: T24 DCV/Occ Standby
A5: Exam Room | B5: 5 | C5: 0.06 | D5: 2.5 | E5: 0.3 | F5: 5 | G5: 0.15 | H5: 0 | I5: 0.15 | J5: *DON'T WANT TO MAKE AS AN OFFICE SPACE | K5: ADDED CATEGORY
A6: Imaging Room | B6: 5 | C6: 0.06 | D6: 2.5 | E6: 0.3 | F6: 5 | G6: 0.15 | H6: 0 | I6: 0.15 | K6: ADDED CATEGORY
A7: Waiting Room | B7: 5 | C7: 0.06 | D7: 3.8 | E7: 0.3 | F7: 30 | G7: =VLOOKUP(A7,'T-24 TAble 120.1-A'!$A$2:$D$76,2,FALSE) -> #N/A | H7: =VLOOKUP(A7,'T-24 TAble 120.1-A'!$A$2:$D$76,3,FALSE) -> #N/A | I7: =IF(VLOOKUP(A7,'T-24 TAble 120.1-A'!$A$2:$D$76,7,FALSE)="F",0,H7) -> #N/A | J7: *CLASS F | K7: ADDED CATEGORY
A8: Nurse Station | B8: 5 | C8: 0.06 | D8: 3.8 | E8: 0.3 | F8: 15 | G8: 0.15 | H8: 0 | I8: 0.15 | J8: *SAME AS OFFICE SPACE AND CLASS F | K8: ADDED CATEGORY
A9: Procedure Room | B9: 5 | C9: 0.15 | D9: 5 | E9: 0.3 | F9: 5 | G9: 0.15 | H9: 0 | I9: 0.15
A10: Barracks sleeping areas | B10: 5 | C10: 0.06 | D10: 2.5 | E10: 0.3 | F10: 20 | G10: =VLOOKUP(A10,'T-24 TAble 120.1-A'!$A$2:$D$76,2,FALSE) -> #N/A | H10: =VLOOKUP(A10,'T-24 TAble 120.1-A'!$A$2:$D$76,3,FALSE) -> #N/A | I10: =IF(VLOOKUP(A10,'T-24 TAble 120.1-A'!$A$2:$D$76,7,FALSE)="F",0,H10) -> #N/A
A11: Bars, cocktail lounges | B11: 7.5 | C11: 0.18 | D11: 3.8 | E11: 0.9 | F11: 100 | G11: =VLOOKUP(A11,'T-24 TAble 120.1-A'!$A$2:$D$76,2,FALSE) -> #N/A | H11: =VLOOKUP(A11,'T-24 TAble 120.1-A'!$A$2:$D$76,3,FALSE) -> #N/A | I11: =IF(VLOOKUP(A11,'T-24 TAble 120.1-A'!$A$2:$D$76,7,FALSE)="F",0,H11) -> #N/A
A12: Beauty and nail salons | B12: 20 | C12: 0.12 | D12: 10 | E12: 0.6 | F12: 25 | G12: =VLOOKUP(A12,'T-24 TAble 120.1-A'!$A$2:$D$76,2,FALSE) -> #N/A | H12: =VLOOKUP(A12,'T-24 TAble 120.1-A'!$A$2:$D$76,3,FALSE) -> #N/A | I12: =IF(VLOOKUP(A12,'T-24 TAble 120.1-A'!$A$2:$D$76,7,FALSE)="F",0,H12) -> #N/A
A13: Bedroom/living room | B13: 5 | C13: 0.06 | D13: 2.5 | E13: 0.3 | F13: 10 | G13: =VLOOKUP(A13,'T-24 TAble 120.1-A'!$A$2:$D$76,2,FALSE) -> #N/A | H13: =VLOOKUP(A13,'T-24 TAble 120.1-A'!$A$2:$D$76,3,FALSE) -> #N/A | I13: =IF(VLOOKUP(A13,'T-24 TAble 120.1-A'!$A$2:$D$76,7,FALSE)="F",0,H13) -> #N/A
A14: Booking/waiting | B14: 7.5 | C14: 0.06 | D14: 3.8 | E14: 0.3 | F14: 50 | G14: =VLOOKUP(A14,'T-24 TAble 120.1-A'!$A$2:$D$76,2,FALSE) -> #N/A | H14: =VLOOKUP(A14,'T-24 TAble 120.1-A'!$A$2:$D$76,3,FALSE) -> #N/A | I14: =IF(VLOOKUP(A14,'T-24 TAble 120.1-A'!$A$2:$D$76,7,FALSE)="F",0,H14) -> #N/A
A15: Bowling alley (seating) | B15: 10 | C15: 0.12 | D15: 5 | E15: 0.6 | F15: 40 | G15: =VLOOKUP(A15,'T-24 TAble 120.1-A'!$A$2:$D$76,2,FALSE) -> #N/A | H15: =VLOOKUP(A15,'T-24 TAble 120.1-A'!$A$2:$D$76,3,FALSE) -> #N/A | I15: =IF(VLOOKUP(A15,'T-24 TAble 120.1-A'!$A$2:$D$76,7,FALSE)="F",0,H15) -> #N/A
A16: Break rooms | B16: 5 | C16: 0.06 | D16: 2.5 | E16: 0.6 | F16: 25 | G16: =VLOOKUP(A16,'T-24 TAble 120.1-A'!$A$2:$D$76,2,FALSE) -> #N/A | H16: =VLOOKUP(A16,'T-24 TAble 120.1-A'!$A$2:$D$76,3,FALSE) -> #N/A | I16: =IF(VLOOKUP(A16,'T-24 TAble 120.1-A'!$A$2:$D$76,7,FALSE)="F",0,H16) -> #N/A
A17: Cafeteria/fast-food dining | B17: 7.5 | C17: 0.18 | D17: 3.8 | E17: 0.9 | F17: 100 | G17: =VLOOKUP(A17,'T-24 TAble 120.1-A'!$A$2:$D$76,2,FALSE) -> #N/A | H17: =VLOOKUP(A17,'T-24 TAble 120.1-A'!$A$2:$D$76,3,FALSE) -> #N/A | I17: =IF(VLOOKUP(A17,'T-24 TAble 120.1-A'!$A$2:$D$76,7,FALSE)="F",0,H17) -> #N/A
A18: Cell | B18: 5 | C18: 0.12 | D18: 2.5 | E18: 0.6 | F18: 25 | G18: =VLOOKUP(A18,'T-24 TAble 120.1-A'!$A$2:$D$76,2,FALSE) -> #N/A | H18: =VLOOKUP(A18,'T-24 TAble 120.1-A'!$A$2:$D$76,3,FALSE) -> #N/A | I18: =IF(VLOOKUP(A18,'T-24 TAble 120.1-A'!$A$2:$D$76,7,FALSE)="F",0,H18) -> #N/A
A19: Classrooms (age 9 -18) | B19: 10 | C19: 0.12 | D19: 5 | E19: 0.6 | F19: 35 | G19: =VLOOKUP(A19,'T-24 TAble 120.1-A'!$A$2:$D$76,2,FALSE) -> #N/A | H19: =VLOOKUP(A19,'T-24 TAble 120.1-A'!$A$2:$D$76,3,FALSE) -> #N/A | I19: =IF(VLOOKUP(A19,'T-24 TAble 120.1-A'!$A$2:$D$76,7,FALSE)="F",0,H19) -> #N/A
A20: Classrooms (ages 5-8) | B20: 10 | C20: 0.12 | D20: 5 | E20: 0.6 | F20: 25 | G20: =VLOOKUP(A20,'T-24 TAble 120.1-A'!$A$2:$D$76,2,FALSE) -> #N/A | H20: =VLOOKUP(A20,'T-24 TAble 120.1-A'!$A$2:$D$76,3,FALSE) -> #N/A | I20: =IF(VLOOKUP(A20,'T-24 TAble 120.1-A'!$A$2:$D$76,7,FALSE)="F",0,H20) -> #N/A
A21: Coffee stations | B21: 5 | C21: 0.06 | D21: 2.5 | E21: 0.3 | F21: 20 | G21: =VLOOKUP(A21,'T-24 TAble 120.1-A'!$A$2:$D$76,2,FALSE) -> #N/A | H21: =VLOOKUP(A21,'T-24 TAble 120.1-A'!$A$2:$D$76,3,FALSE) -> #N/A | I21: =IF(VLOOKUP(A21,'T-24 TAble 120.1-A'!$A$2:$D$76,7,FALSE)="F",0,H21) -> #N/A
A22: Coin-operated laundries | B22: 7.5 | C22: 0.06 | D22: 3.8 | E22: 0.6 | F22: 20 | G22: =VLOOKUP(A22,'T-24 TAble 120.1-A'!$A$2:$D$76,2,FALSE) -> #N/A | H22: =VLOOKUP(A22,'T-24 TAble 120.1-A'!$A$2:$D$76,3,FALSE) -> #N/A | I22: =IF(VLOOKUP(A22,'T-24 TAble 120.1-A'!$A$2:$D$76,7,FALSE)="F",0,H22) -> #N/A
A23: Common corridors | B23: 0 | C23: 0.06 | D23: 0 | E23: 0.3 | G23: =VLOOKUP(A23,'T-24 TAble 120.1-A'!$A$2:$D$76,2,FALSE) -> #N/A | H23: =VLOOKUP(A23,'T-24 TAble 120.1-A'!$A$2:$D$76,3,FALSE) -> #N/A | I23: =IF(VLOOKUP(A23,'T-24 TAble 120.1-A'!$A$2:$D$76,7,FALSE)="F",0,H23) -> #N/A
A24: Computer (not printing) | B24: 5 | C24: 0.06 | D24: 2.5 | E24: 0.3 | F24: 4 | G24: =VLOOKUP(A24,'T-24 TAble 120.1-A'!$A$2:$D$76,2,FALSE) -> #N/A | H24: =VLOOKUP(A24,'T-24 TAble 120.1-A'!$A$2:$D$76,3,FALSE) -> #N/A | I24: =IF(VLOOKUP(A24,'T-24 TAble 120.1-A'!$A$2:$D$76,7,FALSE)="F",0,H24) -> #N/A
A25: Computer lab | B25: 10 | C25: 0.12 | D25: 5 | E25: 0.6 | F25: 25 | G25: =VLOOKUP(A25,'T-24 TAble 120.1-A'!$A$2:$D$76,2,FALSE) -> #N/A | H25: =VLOOKUP(A25,'T-24 TAble 120.1-A'!$A$2:$D$76,3,FALSE) -> #N/A | I25: =IF(VLOOKUP(A25,'T-24 TAble 120.1-A'!$A$2:$D$76,7,FALSE)="F",0,H25) -> #N/A
A26: Conference/meeting | B26: 5 | C26: 0.06 | D26: 2.5 | E26: 0.3 | F26: 50 | G26: =VLOOKUP(A26,'T-24 TAble 120.1-A'!$A$2:$D$76,2,FALSE) -> #N/A | H26: =VLOOKUP(A26,'T-24 TAble 120.1-A'!$A$2:$D$76,3,FALSE) -> #N/A | I26: =IF(VLOOKUP(A26,'T-24 TAble 120.1-A'!$A$2:$D$76,7,FALSE)="F",0,H26) -> #N/A
A27: Corridors | B27: 0 | C27: 0.06 | D27: 0 | E27: 0.3 | F27: 0 | G27: =VLOOKUP(A27,'T-24 TAble 120.1-A'!$A$2:$D$76,2,FALSE) -> #N/A | H27: =VLOOKUP(A27,'T-24 TAble 120.1-A'!$A$2:$D$76,3,FALSE) -> #N/A | I27: =IF(VLOOKUP(A27,'T-24 TAble 120.1-A'!$A$2:$D$76,7,FALSE)="F",0,H27) -> #N/A
A28: Courtrooms | B28: 5 | C28: 0.06 | D28: 2.5 | E28: 0.3 | F28: 70 | G28: =VLOOKUP(A28,'T-24 TAble 120.1-A'!$A$2:$D$76,2,FALSE) -> #N/A | H28: =VLOOKUP(A28,'T-24 TAble 120.1-A'!$A$2:$D$76,3,FALSE) -> #N/A | I28: =IF(VLOOKUP(A28,'T-24 TAble 120.1-A'!$A$2:$D$76,7,FALSE)="F",0,H28) -> #N/A
A29: Daycare (through age 4) | B29: 10 | C29: 0.18 | D29: 5 | E29: 0.9 | F29: 25 | G29: =VLOOKUP(A29,'T-24 TAble 120.1-A'!$A$2:$D$76,2,FALSE) -> #N/A | H29: =VLOOKUP(A29,'T-24 TAble 120.1-A'!$A$2:$D$76,3,FALSE) -> #N/A | I29: =IF(VLOOKUP(A29,'T-24 TAble 120.1-A'!$A$2:$D$76,7,FALSE)="F",0,H29) -> #N/A
A30: Daycare sickroom | B30: 10 | C30: 0.18 | D30: 5 | E30: 0.9 | F30: 25 | G30: =VLOOKUP(A30,'T-24 TAble 120.1-A'!$A$2:$D$76,2,FALSE) -> #N/A | H30: =VLOOKUP(A30,'T-24 TAble 120.1-A'!$A$2:$D$76,3,FALSE) -> #N/A | I30: =IF(VLOOKUP(A30,'T-24 TAble 120.1-A'!$A$2:$D$76,7,FALSE)="F",0,H30) -> #N/A
A31: Dayroom | B31: 5 | C31: 0.06 | D31: 2.5 | E31: 0.3 | F31: 30 | G31: =VLOOKUP(A31,'T-24 TAble 120.1-A'!$A$2:$D$76,2,FALSE) -> #N/A | H31: =VLOOKUP(A31,'T-24 TAble 120.1-A'!$A$2:$D$76,3,FALSE) -> #N/A | I31: =IF(VLOOKUP(A31,'T-24 TAble 120.1-A'!$A$2:$D$76,7,FALSE)="F",0,H31) -> #N/A
A32: Disco/dance floors | B32: 20 | C32: 0.06 | D32: 10 | E32: 0.3 | F32: 100 | G32: =VLOOKUP(A32,'T-24 TAble 120.1-A'!$A$2:$D$76,2,FALSE) -> #N/A | H32: =VLOOKUP(A32,'T-24 TAble 120.1-A'!$A$2:$D$76,3,FALSE) -> #N/A | I32: =IF(VLOOKUP(A32,'T-24 TAble 120.1-A'!$A$2:$D$76,7,FALSE)="F",0,H32) -> #N/A
A33: Dwelling unit | B33: 5 | C33: 0.06 | D33: 2.5 | E33: 0.3 | F33: 2 | G33: =VLOOKUP(A33,'T-24 TAble 120.1-A'!$A$2:$D$76,2,FALSE) -> #N/A | H33: =VLOOKUP(A33,'T-24 TAble 120.1-A'!$A$2:$D$76,3,FALSE) -> #N/A | I33: =IF(VLOOKUP(A33,'T-24 TAble 120.1-A'!$A$2:$D$76,7,FALSE)="F",0,H33) -> #N/A
A34: Electrical equipment rooms | B34: 0 | C34: 0.06 | D34: 0 | E34: 0.3 | F34: 0 | G34: 0.15 | H34: =VLOOKUP(A34,'T-24 TAble 120.1-A'!$A$2:$D$76,3,FALSE) -> #N/A | I34: =IF(VLOOKUP(A34,'T-24 TAble 120.1-A'!$A$2:$D$76,7,FALSE)="F",0,H34) -> #N/A
A35: Elevator machine rooms | B35: 0 | C35: 0.12 | D35: 0 | E35: 0.6 | F35: 0 | G35: 0.15 | H35: =VLOOKUP(A35,'T-24 TAble 120.1-A'!$A$2:$D$76,3,FALSE) -> #N/A | I35: =IF(VLOOKUP(A35,'T-24 TAble 120.1-A'!$A$2:$D$76,7,FALSE)="F",0,H35) -> #N/A
A36: Gambling casinos | B36: 7.5 | C36: 0.18 | D36: 3.8 | E36: 0.9 | F36: 120 | G36: =VLOOKUP(A36,'T-24 TAble 120.1-A'!$A$2:$D$76,2,FALSE) -> #N/A | H36: =VLOOKUP(A36,'T-24 TAble 120.1-A'!$A$2:$D$76,3,FALSE) -> #N/A | I36: =IF(VLOOKUP(A36,'T-24 TAble 120.1-A'!$A$2:$D$76,7,FALSE)="F",0,H36) -> #N/A
A37: Game arcades | B37: 7.5 | C37: 0.18 | D37: 3.8 | E37: 0.9 | F37: 20 | G37: =VLOOKUP(A37,'T-24 TAble 120.1-A'!$A$2:$D$76,2,FALSE) -> #N/A | H37: =VLOOKUP(A37,'T-24 TAble 120.1-A'!$A$2:$D$76,3,FALSE) -> #N/A | I37: =IF(VLOOKUP(A37,'T-24 TAble 120.1-A'!$A$2:$D$76,7,FALSE)="F",0,H37) -> #N/A
A38: General manufacturing (excludes heavy industrial and process using chemicals) | B38: 10 | C38: 0.18 | D38: 5 | E38: 0.9 | F38: 7 | G38: =VLOOKUP(A38,'T-24 TAble 120.1-A'!$A$2:$D$76,2,FALSE) -> #N/A | H38: =VLOOKUP(A38,'T-24 TAble 120.1-A'!$A$2:$D$76,3,FALSE) -> #N/A | I38: =IF(VLOOKUP(A38,'T-24 TAble 120.1-A'!$A$2:$D$76,7,FALSE)="F",0,H38) -> #N/A
A39: Guard stations | B39: 5 | C39: 0.06 | D39: 2.5 | E39: 0.3 | F39: 15 | G39: =VLOOKUP(A39,'T-24 TAble 120.1-A'!$A$2:$D$76,2,FALSE) -> #N/A | H39: =VLOOKUP(A39,'T-24 TAble 120.1-A'!$A$2:$D$76,3,FALSE) -> #N/A | I39: =IF(VLOOKUP(A39,'T-24 TAble 120.1-A'!$A$2:$D$76,7,FALSE)="F",0,H39) -> #N/A
A40: Gym, sports arena (play area) | B40: 0 | C40: 0.3 | D40: 0 | E40: 1.5 | F40: 30 | G40: =VLOOKUP(A40,'T-24 TAble 120.1-A'!$A$2:$D$76,2,FALSE) -> #N/A | H40: =VLOOKUP(A40,'T-24 TAble 120.1-A'!$A$2:$D$76,3,FALSE) -> #N/A | I40: =IF(VLOOKUP(A40,'T-24 TAble 120.1-A'!$A$2:$D$76,7,FALSE)="F",0,H40) -> #N/A
A41: Health club/aerobics room | B41: 20 | C41: 0.06 | D41: 10 | E41: 0.3 | F41: 40 | G41: =VLOOKUP(A41,'T-24 TAble 120.1-A'!$A$2:$D$76,2,FALSE) -> #N/A | H41: =VLOOKUP(A41,'T-24 TAble 120.1-A'!$A$2:$D$76,3,FALSE) -> #N/A | I41: =IF(VLOOKUP(A41,'T-24 TAble 120.1-A'!$A$2:$D$76,7,FALSE)="F",0,H41) -> #N/A
...

Sheet T-24 TAble 120.1-A
A1: Occupancy Category | B1: Total Outdoor Air Rate1 Rt (cfm/ft2) | C1: Min Ventilation Air Rate for DCV2 Ra (cfm/ft2) | D1: Air Class | E1: OS
A2: Educational Facilities - Daycare (through age 4) | B2: 0.21 | C2: 0.15 | D2: 2
A3: Educational Facilities - Daycare sickroom | B3: 0.15 | D3: 3
A4: Educational Facilities - Classrooms (ages 5-8) | B4: 0.38 | C4: 0.15 | D4: 1
A5: Educational Facilities - Classrooms (age 9 -18) | B5: 0.38 | C5: 0.15 | D5: 1
A6: Educational Facilities - Lecture/postsecondary classroom | B6: 0.38 | C6: 0.15 | D6: 1 | E6: YES
A7: Educational Facilities - Lecture hall (fixed seats) | B7: 0 | C7: 0.15 | D7: 1 | E7: YES
A8: Educational Facilities - Art classroom | B8: 0.15 | D8: 2
A9: Educational Facilities - Science laboratories | B9: 0.15 | D9: 2
A10: Educational Facilities - University/college laboratories | B10: 0.15 | D10: 2
A11: Educational Facilities - University/college laboratories | B11: 0.15 | D11: 2
A12: Educational Facilities - Computer lab | B12: 0.15 | D12: 1
A13: Educational Facilities - Media center | B13: 0.15 | D13: 1
A14: Educational Facilities - Music/theater/dance | B14: 1.07 | C14: 0.15 | D14: 1 | E14: YES
A15: Educational Facilities - Multiuse assembly | B15: 0.5 | C15: 0.15 | D15: 1 | E15: YES
A16: Food and Beverage Service - Restaurant dining rooms | B16: 0.5 | C16: 0.15 | D16: 2
A17: Food and Beverage Service - Cafeteria/fast-food dining | B17: 0.5 | C17: 0.15 | D17: 2
A18: Food and Beverage Service - Bars, cocktail lounges | B18: 0.5 | C18: 0.2 | D18: 2
A19: Food and Beverage Service - Kitchen (cooking) | B19: 0.15 | D19: 2
A20: General - Break rooms (not office) | B20: 0.5 | C20: 0.15 | D20: 1 | E20: YES
A21: General - Coffee Stations | B21: 0.5 | C21: 0.15 | D21: 1 | E21: YES
A22: General - Conference/meeting | B22: 0.5 | C22: 0.15 | D22: 1 | E22: YES
A23: General - Corridors | B23: 0.15 | D23: 1 | E23: YES
A24: General - Occupiable storage rooms for liquids or gels | B24: 0.15 | D24: 2 | E24: YES
A25: Hotels, Motels, Resorts, Dormitories - Bedroom/living room | B25: 0.15 | D25: 1 | E25: YES
A26: Hotels, Motels, Resorts, Dormitories - Barracks sleeping areas | B26: 0.15 | D26: 1 | E26: YES
A27: Hotels, Motels, Resorts, Dormitories - Laundry rooms, central | B27: 0.15 | D27: 2
A28: Hotels, Motels, Resorts, Dormitories - Laundry rooms within dwelling units | B28: 0.15 | D28: 1
A29: Hotels, Motels, Resorts, Dormitories - Lobbies/pre-function | B29: 0.5 | C29: 0.15 | D29: 1 | E29: YES
A30: Hotels, Motels, Resorts, Dormitories - Multipurpose assembly | B30: 0.5 | D30: 1 | E30: YES
A31: Office Buildings - Break rooms | B31: 0.5 | C31: 0.15 | D31: 1
A32: Office Buildings - Main entry lobbies | B32: 0.5 | C32: 0.15 | D32: 1 | E32: YES
A33: Office Buildings - storage rooms | B33: 0.15 | D33: 1
A34: Office Buildings - Office space | B34: 0.15 | D34: 1 | E34: YES
A35: Office Buildings - Reception areas | B35: 0.15 | D35: 1 | E35: YES
A36: Office Buildings - Telephone/data entry | B36: 0.15 | D36: 1 | E36: YES
A37: Miscellaneous Spaces - Bank vaults/safe deposit | B37: 0.15 | D37: 2 | E37: YES
A38: Miscellaneous Spaces - Banks or bank lobbies | B38: 0.15 | D38: 1 | E38: YES
A39: Miscellaneous Spaces - Computer (not printing) | B39: 0.15 | D39: 1 | E39: YES
A40: Miscellaneous Spaces - Freezer and refrigerated spaces (<50oF) | B40: - | D40: 2
...

Sheet RTU 1-1
A1: IP
B2: VAV-1-1-1 | C2: VAV-1-1-2 | D2: VAV-1-1-3 | E2: VAV-1-2-1 | F2: VAV-1-2-2 | G2: VAV-1-2-3 | H2: VAV-1-2-4 | I2: VAV-1-2-5 | J2: VAV-1-3-1 | K2: VAV-1-3-2 | L2: VAV-1-3-3 | M2: VAV-1-3-4 | N2: VAV-1-3-5 | O2: VAV-1-3-6 | P2: VAV-1-3-7 | Q2: VAV-1-4-1 | R2: VAV-1-4-2 | S2: VAV-1-4-3 | T2: VAV-1-4-4 | U2: VAV-1-5-1 | V2: VAV-1-5-2 | W2: VAV-1-5-3 | AB2: new zone | AC2: Totals/averages
AB3: New zone ID
A4: Room Type | B4: Sales (except as below) | C4: Pharmacy (prep. area) | D4: Storage rooms | E4: Exam Room | F4: Nurse Station | G4: Nurse Station | H4: Nurse Station | I4: Conference/meeting | J4: Main entry lobbies | K4: Storage rooms | L4: Break rooms | M4: Nurse Station | N4: Office space | O4: Nurse Station | P4: Nurse Station | Q4: Laundry rooms, central | R4: Electrical equipment rooms | S4: Nurse Station | T4: Office space | U4: Waiting Room | V4: Waiting Room | W4: Exam Room | X4: Office space | Y4: Office space | Z4: Office space | AA4: Office space | AB4: Office space
A5: Area | B5: 524 | C5: 763 | D5: 169 | E5: 692.1 | F5: 313.9 | G5: 451 | H5: 651.1 | I5: 390 | J5: 641.1 | K5: 561.2 | L5: 387 | M5: 295.2 | N5: 763.4 | O5: 190 | P5: 292 | Q5: 400 | R5: 679 | S5: 502 | T5: 555.5 | U5: 672 | V5: 228.7 | W5: 181.5 | AB5: =SUM(B5:AA5) -> 10302.7 | AC5: sq. ft.
A6: People | B6: =B5*VLOOKUP(B4,'Table 6-1 Rates'!$A$4:$F$84,6,FALSE)/IF($A$1="IP",1000,100) -> 7.86 | C6: =C5*VLOOKUP(C4,'Table 6-1 Rates'!$A$4:$F$84,6,FALSE)/IF($A$1="IP",1000,100) -> 7.63 | D6: =D5*VLOOKUP(D4,'Table 6-1 Rates'!$A$4:$F$84,6,FALSE)/IF($A$1="IP",1000,100) -> 0.338 | E6: =E5*VLOOKUP(E4,'Table 6-1 Rates'!$A$4:$F$84,6,FALSE)/IF($A$1="IP",1000,100) -> 3.4605 | F6: =F5*VLOOKUP(F4,'Table 6-1 Rates'!$A$4:$F$84,6,FALSE)/IF($A$1="IP",1000,100) -> 4.7085 | G6: =G5*VLOOKUP(G4,'Table 6-1 Rates'!$A$4:$F$84,6,FALSE)/IF($A$1="IP",1000,100) -> 6.765 | H6: =H5*VLOOKUP(H4,'Table 6-1 Rates'!$A$4:$F$84,6,FALSE)/IF($A$1="IP",1000,100) -> 9.7665 | I6: =I5*VLOOKUP(I4,'Table 6-1 Rates'!$A$4:$F$84,6,FALSE)/IF($A$1="IP",1000,100) -> 19.5 | ... AA6: =AA5*VLOOKUP(AA4,'Table 6-1 Rates'!$A$4:$F$84,6,FALSE)/IF($A$1="IP",1000,100) -> 0 | AB6: =SUM(B6:AA6) -> 134.9479 | AC6: People
A7: VareaMin T-24 | B7: =B5*(VLOOKUP(B4,'Table 6-1 Rates'!$A$3:$I$84,7,FALSE)) -> #N/A | C7: =C5*(VLOOKUP(C4,'Table 6-1 Rates'!$A$3:$I$84,7,FALSE)) -> #N/A | D7: =D5*(VLOOKUP(D4,'Table 6-1 Rates'!$A$3:$I$84,7,FALSE)) -> #N/A | E7: =E5*(VLOOKUP(E4,'Table 6-1 Rates'!$A$3:$I$84,7,FALSE)) -> 103.815 | F7: =F5*(VLOOKUP(F4,'Table 6-1 Rates'!$A$3:$I$84,7,FALSE)) -> 47.085 | G7: =G5*(VLOOKUP(G4,'Table 6-1 Rates'!$A$3:$I$84,7,FALSE)) -> 67.65 | H7: =H5*(VLOOKUP(H4,'Table 6-1 Rates'!$A$3:$I$84,7,FALSE)) -> 97.665 | I7: =I5*(VLOOKUP(I4,'Table 6-1 Rates'!$A$3:$I$84,7,FALSE)) -> #N/A | ... AA7: =AA5*(VLOOKUP(AA4,'Table 6-1 Rates'!$A$3:$I$84,7,FALSE)) -> #N/A | AB7: {=SUM(IFERROR(A7:AA7,0))} -> 637.17
A8: Voccmin T-24 DCV | B8: =B5*(VLOOKUP(B4,'Table 6-1 Rates'!$A$3:$I$84,8,FALSE)) -> #N/A | C8: =C5*(VLOOKUP(C4,'Table 6-1 Rates'!$A$3:$I$84,8,FALSE)) -> #N/A | D8: =D5*(VLOOKUP(D4,'Table 6-1 Rates'!$A$3:$I$84,8,FALSE)) -> #N/A | E8: =E5*(VLOOKUP(E4,'Table 6-1 Rates'!$A$3:$I$84,8,FALSE)) -> 0 | F8: =F5*(VLOOKUP(F4,'Table 6-1 Rates'!$A$3:$I$84,8,FALSE)) -> 0 | G8: =G5*(VLOOKUP(G4,'Table 6-1 Rates'!$A$3:$I$84,8,FALSE)) -> 0 | H8: =H5*(VLOOKUP(H4,'Table 6-1 Rates'!$A$3:$I$84,8,FALSE)) -> 0 | I8: =I5*(VLOOKUP(I4,'Table 6-1 Rates'!$A$3:$I$84,8,FALSE)) -> #N/A | ... AA8: =AA5*(VLOOKUP(AA4,'Table 6-1 Rates'!$A$3:$I$84,8,FALSE)) -> #N/A | AB8: {=SUM(IFERROR(A8:AA8,0))} -> 0
A9: VoccMin OccStandby | B9: =B5*(VLOOKUP(B4,'Table 6-1 Rates'!$A$3:$I$84,9,FALSE)) -> #N/A | C9: =C5*(VLOOKUP(C4,'Table 6-1 Rates'!$A$3:$I$84,9,FALSE)) -> #N/A | D9: =D5*(VLOOKUP(D4,'Table 6-1 Rates'!$A$3:$I$84,9,FALSE)) -> #N/A | E9: =E5*(VLOOKUP(E4,'Table 6-1 Rates'!$A$3:$I$84,9,FALSE)) -> 103.815 | F9: =F5*(VLOOKUP(F4,'Table 6-1 Rates'!$A$3:$I$84,9,FALSE)) -> 47.085 | G9: =G5*(VLOOKUP(G4,'Table 6-1 Rates'!$A$3:$I$84,9,FALSE)) -> 67.65 | H9: =H5*(VLOOKUP(H4,'Table 6-1 Rates'!$A$3:$I$84,9,FALSE)) -> 97.665 | I9: =I5*(VLOOKUP(I4,'Table 6-1 Rates'!$A$3:$I$84,9,FALSE)) -> #N/A | ... AA9: =AA5*(VLOOKUP(AA4,'Table 6-1 Rates'!$A$3:$I$84,9,FALSE)) -> #N/A | AB9: {=SUM(IFERROR(B9:AA9,0))} -> 535.32
A10: OccSensor Req | B10: =IF(VLOOKUP('RTU 1-1'!B4,'T-24 TAble 120.1-A'!$A$2:$D$76,7,FALSE)="F","YES","NO") -> #N/A | C10: =IF(VLOOKUP('RTU 1-1'!C4,'T-24 TAble 120.1-A'!$A$2:$D$76,7,FALSE)="F","YES","NO") -> #N/A | D10: =IF(VLOOKUP('RTU 1-1'!D4,'T-24 TAble 120.1-A'!$A$2:$D$76,7,FALSE)="F","YES","NO") -> #N/A | E10: =IF(VLOOKUP('RTU 1-1'!E4,'T-24 TAble 120.1-A'!$A$2:$D$76,7,FALSE)="F","YES","NO") -> #N/A | F10: =IF(VLOOKUP('RTU 1-1'!F4,'T-24 TAble 120.1-A'!$A$2:$D$76,7,FALSE)="F","YES","NO") -> #N/A | G10: =IF(VLOOKUP('RTU 1-1'!G4,'T-24 TAble 120.1-A'!$A$2:$D$76,7,FALSE)="F","YES","NO") -> #N/A | H10: =IF(VLOOKUP('RTU 1-1'!H4,'T-24 TAble 120.1-A'!$A$2:$D$76,7,FALSE)="F","YES","NO") -> #N/A | I10: =IF(VLOOKUP('RTU 1-1'!I4,'T-24 TAble 120.1-A'!$A$2:$D$76,7,FALSE)="F","YES","NO") -> #N/A | ... Y10: =IF(VLOOKUP('RTU 1-1'!Y4,'T-24 TAble 120.1-A'!$A$2:$D$76,7,FALSE)="F","YES","NO") -> #N/A | Z10: RTU 1-1 | AA10: ABSMIN | AB10: =AB9 -> 535.32
A11: co2 REQ? | B11: =IF(VLOOKUP(B4,'Table 6-1 Rates'!$A$5:$I$84,6,FALSE)>25,"YES","NO") -> NO | C11: =IF(VLOOKUP(C4,'Table 6-1 Rates'!$A$5:$I$84,6,FALSE)>25,"YES","NO") -> NO | D11: =IF(VLOOKUP(D4,'Table 6-1 Rates'!$A$5:$I$84,6,FALSE)>25,"YES","NO") -> NO | E11: =IF(VLOOKUP(E4,'Table 6-1 Rates'!$A$5:$I$84,6,FALSE)>25,"YES","NO") -> NO | F11: =IF(VLOOKUP(F4,'Table 6-1 Rates'!$A$5:$I$84,6,FALSE)>25,"YES","NO") -> NO | G11: =IF(VLOOKUP(G4,'Table 6-1 Rates'!$A$5:$I$84,6,FALSE)>25,"YES","NO") -> NO | H11: =IF(VLOOKUP(H4,'Table 6-1 Rates'!$A$5:$I$84,6,FALSE)>25,"YES","NO") -> NO | I11: =IF(VLOOKUP(I4,'Table 6-1 Rates'!$A$5:$I$84,6,FALSE)>25,"YES","NO") -> YES | ... Y11: =IF(VLOOKUP(Y4,'Table 6-1 Rates'!$A$5:$I$84,6,FALSE)>25,"YES","NO") -> NO | AA11: DESMINOA | AB11: =SUM(AB7) -> 637.17

Sheet RTU 2-X
A1: IP
B2: VAV-2-1-1 | C2: VAV-2-1-2 | D2: VAV-2-1-3 | E2: VAV-2-2-1 | F2: VAV-2-2-2 | G2: VAV-2-2-3 | H2: VAV-2-2-4 | I2: VAV-2-2-5 | J2: VAV-2-2-6 | K2: VAV-2-3-1 | L2: VAV-2-3-2 | M2: VAV-2-3-3 | N2: VAV-2-3-4 | O2: VAV-2-3-5 | P2: VAV-2-3-6 | Q2: VAV-2-3-7 | R2: VAV-2-4-1 | S2: VAV-2-4-2 | T2: VAV-2-4-3 | U2: VAV-2-4-4 | V2: VAV-2-4-5 | W2: VAV-2-4-6 | X2: VAV-2-4-7 | Y2: VAV-2-4-8 | Z2: VAV-2-4-9 | AA2: VAV-2-5-1 | AB2: VAV-2-5-2 | AC2: VAV-2-5-3 | AD2: VAV-2-5-4 | AE2: VAV-2-5-5 | AF2: VAV-2-5-6 | AG2: VAV-2-5-7 | AH2: new zone | AI2: Totals/averages
AH3: New zone ID
A4: Room Type | B4: Corridors | C4: Exam Room | D4: Exam Room | E4: Exam Room | F4: Exam Room | G4: Exam Room | H4: Nurse Station | I4: Waiting Room | J4: Exam Room | K4: Exam Room | L4: Exam Room | M4: Exam Room | N4: Exam Room | O4: Corridors | P4: Nurse Station | Q4: Conference/meeting | R4: Exam Room | S4: Exam Room | T4: Exam Room | U4: Exam Room | V4: Exam Room | W4: Exam Room | X4: Corridors | Y4: Exam Room | Z4: Nurse Station | AA4: Main entry lobbies | AB4: Storage rooms | AC4: Waiting Room | AD4: Corridors | AE4: Waiting Room | AF4: Exam Room | AG4: Waiting Room | AH4: Office space
A5: Area | B5: 351 | C5: 105 | D5: 400 | E5: 296.8 | F5: 379.8 | G5: 382.7 | H5: 712.8 | I5: 361.8 | J5: 627.4 | K5: 410 | L5: 200 | M5: 100.8 | N5: 105.3 | O5: 220 | P5: 215 | Q5: 312 | R5: 109 | S5: 297 | T5: 297 | U5: 198.8 | V5: 100.8 | W5: 110 | X5: 200 | Y5: 123.8 | Z5: 325 | AA5: 440 | AB5: 108.8 | AC5: 496 | AD5: 987 | AE5: 131 | AF5: 591.4 | AG5: 200 | AH5: =SUM(B5:AG5) -> 9896
A6: People | B6: =B5*VLOOKUP(B4,'Table 6-1 Rates'!$A$4:$F$84,6,FALSE)/IF($A$1="IP",1000,100) -> 0 | C6: =C5*VLOOKUP(C4,'Table 6-1 Rates'!$A$4:$F$84,6,FALSE)/IF($A$1="IP",1000,100) -> 0.525 | D6: =D5*VLOOKUP(D4,'Table 6-1 Rates'!$A$4:$F$84,6,FALSE)/IF($A$1="IP",1000,100) -> 2 | E6: =E5*VLOOKUP(E4,'Table 6-1 Rates'!$A$4:$F$84,6,FALSE)/IF($A$1="IP",1000,100) -> 1.484 | F6: =F5*VLOOKUP(F4,'Table 6-1 Rates'!$A$4:$F$84,6,FALSE)/IF($A$1="IP",1000,100) -> 1.899 | G6: =G5*VLOOKUP(G4,'Table 6-1 Rates'!$A$4:$F$84,6,FALSE)/IF($A$1="IP",1000,100) -> 1.9135 | H6: =H5*VLOOKUP(H4,'Table 6-1 Rates'!$A$4:$F$84,6,FALSE)/IF($A$1="IP",1000,100) -> 10.692 | I6: =I5*VLOOKUP(I4,'Table 6-1 Rates'!$A$4:$F$84,6,FALSE)/IF($A$1="IP",1000,100) -> 10.854 | ... AG6: =AG5*VLOOKUP(AG4,'Table 6-1 Rates'!$A$4:$F$84,6,FALSE)/IF($A$1="IP",1000,100) -> 6 | AH6: =SUM(B6:AG6) -> 98.8516
A7: VareaMin T-24 | B7: =B5*(VLOOKUP(B4,'Table 6-1 Rates'!$A$3:$I$84,7,FALSE)) -> #N/A | C7: =C5*(VLOOKUP(C4,'Table 6-1 Rates'!$A$3:$I$84,7,FALSE)) -> 15.75 | D7: =D5*(VLOOKUP(D4,'Table 6-1 Rates'!$A$3:$I$84,7,FALSE)) -> 60 | E7: =E5*(VLOOKUP(E4,'Table 6-1 Rates'!$A$3:$I$84,7,FALSE)) -> 44.52 | F7: =F5*(VLOOKUP(F4,'Table 6-1 Rates'!$A$3:$I$84,7,FALSE)) -> 56.97 | G7: =G5*(VLOOKUP(G4,'Table 6-1 Rates'!$A$3:$I$84,7,FALSE)) -> 57.405 | H7: =H5*(VLOOKUP(H4,'Table 6-1 Rates'!$A$3:$I$84,7,FALSE)) -> 106.92 | I7: =I5*(VLOOKUP(I4,'Table 6-1 Rates'!$A$3:$I$84,7,FALSE)) -> #N/A | ... AG7: =AG5*(VLOOKUP(AG4,'Table 6-1 Rates'!$A$3:$I$84,7,FALSE)) -> #N/A | AH7: {=SUM(IFERROR(A7:AG7,0))} -> 913.26
A8: Voccmin T-24 DCV | B8: =B5*(VLOOKUP(B4,'Table 6-1 Rates'!$A$3:$I$84,8,FALSE)) -> #N/A | C8: =C5*(VLOOKUP(C4,'Table 6-1 Rates'!$A$3:$I$84,8,FALSE)) -> 0 | D8: =D5*(VLOOKUP(D4,'Table 6-1 Rates'!$A$3:$I$84,8,FALSE)) -> 0 | E8: =E5*(VLOOKUP(E4,'Table 6-1 Rates'!$A$3:$I$84,8,FALSE)) -> 0 | F8: =F5*(VLOOKUP(F4,'Table 6-1 Rates'!$A$3:$I$84,8,FALSE)) -> 0 | G8: =G5*(VLOOKUP(G4,'Table 6-1 Rates'!$A$3:$I$84,8,FALSE)) -> 0 | H8: =H5*(VLOOKUP(H4,'Table 6-1 Rates'!$A$3:$I$84,8,FALSE)) -> 0 | I8: =I5*(VLOOKUP(I4,'Table 6-1 Rates'!$A$3:$I$84,8,FALSE)) -> #N/A | ... AG8: =AG5*(VLOOKUP(AG4,'Table 6-1 Rates'!$A$3:$I$84,8,FALSE)) -> #N/A | AH8: {=SUM(IFERROR(A8:AG8,0))} -> 0
A9: VoccMin OccStandby | B9: =B5*(VLOOKUP(B4,'Table 6-1 Rates'!$A$3:$I$84,9,FALSE)) -> #N/A | C9: =C5*(VLOOKUP(C4,'Table 6-1 Rates'!$A$3:$I$84,9,FALSE)) -> 15.75 | D9: =D5*(VLOOKUP(D4,'Table 6-1 Rates'!$A$3:$I$84,9,FALSE)) -> 60 | E9: =E5*(VLOOKUP(E4,'Table 6-1 Rates'!$A$3:$I$84,9,FALSE)) -> 44.52 | F9: =F5*(VLOOKUP(F4,'Table 6-1 Rates'!$A$3:$I$84,9,FALSE)) -> 56.97 | G9: =G5*(VLOOKUP(G4,'Table 6-1 Rates'!$A$3:$I$84,9,FALSE)) -> 57.405 | H9: =H5*(VLOOKUP(H4,'Table 6-1 Rates'!$A$3:$I$84,9,FALSE)) -> 106.92 | I9: =I5*(VLOOKUP(I4,'Table 6-1 Rates'!$A$3:$I$84,9,FALSE)) -> #N/A | ... AG9: =AG5*(VLOOKUP(AG4,'Table 6-1 Rates'!$A$3:$I$84,9,FALSE)) -> #N/A | AH9: {=SUM(IFERROR(B9:AG9,0))} -> 913.26
A10: OccSensor Req | B10: =IF(VLOOKUP(B4,'T-24 TAble 120.1-A'!$A$2:$D$76,7,FALSE)="F","YES","NO") -> #N/A | C10: =IF(VLOOKUP(C4,'T-24 TAble 120.1-A'!$A$2:$D$76,7,FALSE)="F","YES","NO") -> #N/A | D10: =IF(VLOOKUP(D4,'T-24 TAble 120.1-A'!$A$2:$D$76,7,FALSE)="F","YES","NO") -> #N/A | E10: =IF(VLOOKUP(E4,'T-24 TAble 120.1-A'!$A$2:$D$76,7,FALSE)="F","YES","NO") -> #N/A | F10: =IF(VLOOKUP(F4,'T-24 TAble 120.1-A'!$A$2:$D$76,7,FALSE)="F","YES","NO") -> #N/A | G10: =IF(VLOOKUP(G4,'T-24 TAble 120.1-A'!$A$2:$D$76,7,FALSE)="F","YES","NO") -> #N/A | H10: =IF(VLOOKUP(H4,'T-24 TAble 120.1-A'!$A$2:$D$76,7,FALSE)="F","YES","NO") -> #N/A | I10: =IF(VLOOKUP(I4,'T-24 TAble 120.1-A'!$A$2:$D$76,7,FALSE)="F","YES","NO") -> #N/A | ... AG10: =IF(VLOOKUP(AG4,'T-24 TAble 120.1-A'!$A$2:$D$76,7,FALSE)="F","YES","NO") -> #N/A
A11: co2 REQ? | B11: =IF(VLOOKUP(B4,'Table 6-1 Rates'!$A$5:$I$84,6,FALSE)>25,"YES","NO") -> NO | C11: =IF(VLOOKUP(C4,'Table 6-1 Rates'!$A$5:$I$84,6,FALSE)>25,"YES","NO") -> NO | D11: =IF(VLOOKUP(D4,'Table 6-1 Rates'!$A$5:$I$84,6,FALSE)>25,"YES","NO") -> NO | E11: =IF(VLOOKUP(E4,'Table 6-1 Rates'!$A$5:$I$84,6,FALSE)>25,"YES","NO") -> NO | F11: =IF(VLOOKUP(F4,'Table 6-1 Rates'!$A$5:$I$84,6,FALSE)>25,"YES","NO") -> NO | G11: =IF(VLOOKUP(G4,'Table 6-1 Rates'!$A$5:$I$84,6,FALSE)>25,"YES","NO") -> NO | H11: =IF(VLOOKUP(H4,'Table 6-1 Rates'!$A$5:$I$84,6,FALSE)>25,"YES","NO") -> NO | I11: =IF(VLOOKUP(I4,'Table 6-1 Rates'!$A$5:$I$84,6,FALSE)>25,"YES","NO") -> YES | ... AG11: =IF(VLOOKUP(AG4,'Table 6-1 Rates'!$A$5:$I$84,6,FALSE)>25,"YES","NO") -> YES
AF14: RTU 2-X | AG14: ABSMIN | AH14: =AH9 -> 913.26
AG15: DESMINOA | AH15: =SUM(AH7) -> 913.26

Sheet AC-3
A1: IP
B2: VAV-3-1 | C2: VAV-3-2 | D2: VAV-3-3 | E2: VAV-3-4 | F2: VAV-3-5 | G2: VAV-3-6 | H2: VAV-3-7 | I2: VAV-3-8 | J2: VAV-3-9 | K2: VAV-3-10 | L2: VAV-3-11 | M2: VAV-3-12 | N2: VAV-3-13 | O2: VAV-3-14 | P2: VAV-3-15 | Q2: VAV-3-16 | R2: VAV-3-17 | S2: VAV-3-18 | V2: new zone | W2: Totals/averages
B3: OEXPO | C3: HALLW | D3: LOBBY | E3: GROUP | F3: WTAGN | G3: OGENL | H3: GROUP | I3: OEXPO | J3: HALLW | K3: OEXPO | L3: OEXPO | M3: WSGEN | N3: OGENL | O3: OEXPO | P3: OGENL | Q3: OEXPO | R3: OEXPO | S3: HALLW | V3: New zone ID
A4: Room Type | B4: Office space | C4: Corridors | D4: Lobbies/pre-function | E4: Conference/meeting | F4: Waiting Room | G4: Office space | H4: Conference/meeting | I4: Office space | J4: Corridors | K4: Office space | L4: Office space | M4: Nurse Station | N4: Office space | O4: Office space | P4: Office space | Q4: Office space | R4: Office space | S4: Corridors | T4: Exam Room | U4: Office space
A5: Area | B5: 1122 | C5: 1492 | D5: 1440 | E5: 528 | F5: 1102 | G5: 184 | H5: 524 | I5: 1129 | J5: 969 | K5: 1136 | L5: 224 | M5: 897 | N5: 246 | O5: 1090 | P5: 329 | Q5: 674 | R5: 667 | S5: 942 | V5: =SUM(B5:U5) -> 14695 | W5: SQ.FT
A6: People | B6: =B5*VLOOKUP(B4,'Table 6-1 Rates'!$A$4:$F$84,6,FALSE)/IF($A$1="IP",1000,100) -> 5.61 | C6: =C5*VLOOKUP(C4,'Table 6-1 Rates'!$A$4:$F$84,6,FALSE)/IF($A$1="IP",1000,100) -> 0 | D6: =D5*VLOOKUP(D4,'Table 6-1 Rates'!$A$4:$F$84,6,FALSE)/IF($A$1="IP",1000,100) -> 43.2 | E6: =E5*VLOOKUP(E4,'Table 6-1 Rates'!$A$4:$F$84,6,FALSE)/IF($A$1="IP",1000,100) -> 26.4 | F6: =F5*VLOOKUP(F4,'Table 6-1 Rates'!$A$4:$F$84,6,FALSE)/IF($A$1="IP",1000,100) -> 33.06 | G6: =G5*VLOOKUP(G4,'Table 6-1 Rates'!$A$4:$F$84,6,FALSE)/IF($A$1="IP",1000,100) -> 0.92 | H6: =H5*VLOOKUP(H4,'Table 6-1 Rates'!$A$4:$F$84,6,FALSE)/IF($A$1="IP",1000,100) -> 26.2 | I6: =I5*VLOOKUP(I4,'Table 6-1 Rates'!$A$4:$F$84,6,FALSE)/IF($A$1="IP",1000,100) -> 5.645 | ... U6: =U5*VLOOKUP(U4,'Table 6-1 Rates'!$A$4:$F$84,6,FALSE)/IF($A$1="IP",1000,100) -> 0 | V6: =SUM(B6:U6) -> 176.32 | W6: PEOPLE
A7: VareaMin T-24 | B7: =B5*(VLOOKUP(B4,'Table 6-1 Rates'!$A$3:$I$84,7,FALSE)) -> #N/A | C7: =C5*(VLOOKUP(C4,'Table 6-1 Rates'!$A$3:$I$84,7,FALSE)) -> #N/A | D7: =D5*(VLOOKUP(D4,'Table 6-1 Rates'!$A$3:$I$84,7,FALSE)) -> #N/A | E7: =E5*(VLOOKUP(E4,'Table 6-1 Rates'!$A$3:$I$84,7,FALSE)) -> #N/A | F7: =F5*(VLOOKUP(F4,'Table 6-1 Rates'!$A$3:$I$84,7,FALSE)) -> #N/A | G7: =G5*(VLOOKUP(G4,'Table 6-1 Rates'!$A$3:$I$84,7,FALSE)) -> #N/A | H7: =H5*(VLOOKUP(H4,'Table 6-1 Rates'!$A$3:$I$84,7,FALSE)) -> #N/A | I7: =I5*(VLOOKUP(I4,'Table 6-1 Rates'!$A$3:$I$84,7,FALSE)) -> #N/A | ... U7: =U5*(VLOOKUP(U4,'Table 6-1 Rates'!$A$3:$I$84,7,FALSE)) -> #N/A | V7: =SUM(B7:U7) -> #N/A
A8: Voccmin T-24 DCV | B8: =B5*(VLOOKUP(B4,'Table 6-1 Rates'!$A$3:$I$84,8,FALSE)) -> #N/A | C8: =C5*(VLOOKUP(C4,'Table 6-1 Rates'!$A$3:$I$84,8,FALSE)) -> #N/A | D8: =D5*(VLOOKUP(D4,'Table 6-1 Rates'!$A$3:$I$84,8,FALSE)) -> #N/A | E8: =E5*(VLOOKUP(E4,'Table 6-1 Rates'!$A$3:$I$84,8,FALSE)) -> #N/A | F8: =F5*(VLOOKUP(F4,'Table 6-1 Rates'!$A$3:$I$84,8,FALSE)) -> #N/A | G8: =G5*(VLOOKUP(G4,'Table 6-1 Rates'!$A$3:$I$84,8,FALSE)) -> #N/A | H8: =H5*(VLOOKUP(H4,'Table 6-1 Rates'!$A$3:$I$84,8,FALSE)) -> #N/A | I8: =I5*(VLOOKUP(I4,'Table 6-1 Rates'!$A$3:$I$84,8,FALSE)) -> #N/A | ... U8: =U5*(VLOOKUP(U4,'Table 6-1 Rates'!$A$3:$I$84,8,FALSE)) -> #N/A | V8: =SUM(B8:U8) -> #N/A
A9: VoccMin OccStandby | B9: =B5*(VLOOKUP(B4,'Table 6-1 Rates'!$A$3:$I$84,9,FALSE)) -> #N/A | C9: =C5*(VLOOKUP(C4,'Table 6-1 Rates'!$A$3:$I$84,9,FALSE)) -> #N/A | D9: =D5*(VLOOKUP(D4,'Table 6-1 Rates'!$A$3:$I$84,9,FALSE)) -> #N/A | E9: =E5*(VLOOKUP(E4,'Table 6-1 Rates'!$A$3:$I$84,9,FALSE)) -> #N/A | F9: =F5*(VLOOKUP(F4,'Table 6-1 Rates'!$A$3:$I$84,9,FALSE)) -> #N/A | G9: =G5*(VLOOKUP(G4,'Table 6-1 Rates'!$A$3:$I$84,9,FALSE)) -> #N/A | H9: =H5*(VLOOKUP(H4,'Table 6-1 Rates'!$A$3:$I$84,9,FALSE)) -> #N/A | I9: =I5*(VLOOKUP(I4,'Table 6-1 Rates'!$A$3:$I$84,9,FALSE)) -> #N/A | ... U9: =U5*(VLOOKUP(U4,'Table 6-1 Rates'!$A$3:$I$84,9,FALSE)) -> #N/A | V9: =SUM(B9:U9) -> #N/A
A10: OccSensor Req | B10: =IF(VLOOKUP(B4,'T-24 TAble 120.1-A'!$A$2:$D$76,7,FALSE)="F","YES","NO") -> #N/A | C10: =IF(VLOOKUP(C4,'T-24 TAble 120.1-A'!$A$2:$D$76,7,FALSE)="F","YES","NO") -> #N/A | D10: =IF(VLOOKUP(D4,'T-24 TAble 120.1-A'!$A$2:$D$76,7,FALSE)="F","YES","NO") -> #N/A | E10: =IF(VLOOKUP(E4,'T-24 TAble 120.1-A'!$A$2:$D$76,7,FALSE)="F","YES","NO") -> #N/A | F10: =IF(VLOOKUP(F4,'T-24 TAble 120.1-A'!$A$2:$D$76,7,FALSE)="F","YES","NO") -> #N/A | G10: =IF(VLOOKUP(G4,'T-24 TAble 120.1-A'!$A$2:$D$76,7,FALSE)="F","YES","NO") -> #N/A | H10: =IF(VLOOKUP(H4,'T-24 TAble 120.1-A'!$A$2:$D$76,7,FALSE)="F","YES","NO") -> #N/A | I10: =IF(VLOOKUP(I4,'T-24 TAble 120.1-A'!$A$2:$D$76,7,FALSE)="F","YES","NO") -> #N/A | ... S10: =IF(VLOOKUP(S4,'T-24 TAble 120.1-A'!$A$2:$D$76,7,FALSE)="F","YES","NO") -> #N/A
A11: co2 REQ? | B11: =IF(VLOOKUP(B4,'Table 6-1 Rates'!$A$5:$I$84,6,FALSE)>25,"YES","NO") -> NO | C11: =IF(VLOOKUP(C4,'Table 6-1 Rates'!$A$5:$I$84,6,FALSE)>25,"YES","NO") -> NO | D11: =IF(VLOOKUP(D4,'Table 6-1 Rates'!$A$5:$I$84,6,FALSE)>25,"YES","NO") -> YES | E11: =IF(VLOOKUP(E4,'Table 6-1 Rates'!$A$5:$I$84,6,FALSE)>25,"YES","NO") -> YES | F11: =IF(VLOOKUP(F4,'Table 6-1 Rates'!$A$5:$I$84,6,FALSE)>25,"YES","NO") -> YES | G11: =IF(VLOOKUP(G4,'Table 6-1 Rates'!$A$5:$I$84,6,FALSE)>25,"YES","NO") -> NO | H11: =IF(VLOOKUP(H4,'Table 6-1 Rates'!$A$5:$I$84,6,FALSE)>25,"YES","NO") -> YES | I11: =IF(VLOOKUP(I4,'Table 6-1 Rates'!$A$5:$I$84,6,FALSE)>25,"YES","NO") -> NO | ... U11: =IF(VLOOKUP(U4,'Table 6-1 Rates'!$A$5:$I$84,6,FALSE)>25,"YES","NO") -> NO
T12: AC-3 | U12: ABSMIN | V12: =V9 -> #N/A
U13: DESMINOA | V13: =V7 -> #N/A

Sheet AUTOCAD
A1: EXISTING TERMINAL UNIT SCHEDULE
A2: TAG | B2: PARENT | C2: PRIMARY OCCUPANCY | D2: AS-BUILT CAPACITIES (SEE NOTE 1) | G2: GUIDELINES 36 CONTROLS SETPOINTS
D3: INLET DIAMETER (IN) | E3: MAX AIRFLOW (CFM) | F3: REHEAT COIL | G3: VCOOL-MAX CFM | H3: VMIN CFM | I3: VHEAT-MAX CFM | J3: MAX dt F | K3: VHEAT-MIN CFM | L3: VOCC-MIN CFM | M3: VAREA-MIN CFM | N3: CO2 REQUIRED | O3: CO2 SETPOINT | P3: OCC SENSOR REQUIRED
A4: {=TRANSPOSE('RTU 1-1'!B2:Y2)} -> VAV-1-1-1 | C4: =HLOOKUP(A4,'RTU 1-1'!$B$2:$Y$11,2,FALSE) -> 0 | L4: =HLOOKUP($A4,'RTU 1-1'!$B$2:$Y$11,7,FALSE) -> #N/A | M4: =HLOOKUP($A4,'RTU 1-1'!$B$2:$Y$11,6,FALSE) -> #N/A | N4: =HLOOKUP($A4,'RTU 1-1'!$B$2:$Y$11,10,FALSE) -> NO | O4: =IF(N4="YES",600,"N/A") -> N/A | P4: =HLOOKUP($A4,'RTU 1-1'!$B$2:$Y$11,9,FALSE) -> #N/A
A5: VAV-1-1-2 | C5: =HLOOKUP(A5,'RTU 1-1'!$B$2:$Y$11,2,FALSE) -> 0 | L5: =HLOOKUP($A5,'RTU 1-1'!$B$2:$Y$11,7,FALSE) -> #N/A | M5: =HLOOKUP($A5,'RTU 1-1'!$B$2:$Y$11,6,FALSE) -> #N/A | N5: =HLOOKUP($A5,'RTU 1-1'!$B$2:$Y$11,10,FALSE) -> NO | O5: =IF(N5="YES",600,"N/A") -> N/A | P5: =HLOOKUP($A5,'RTU 1-1'!$B$2:$Y$11,9,FALSE) -> #N/A
A6: VAV-1-1-3 | C6: =HLOOKUP(A6,'RTU 1-1'!$B$2:$Y$11,2,FALSE) -> 0 | L6: =HLOOKUP($A6,'RTU 1-1'!$B$2:$Y$11,7,FALSE) -> #N/A | M6: =HLOOKUP($A6,'RTU 1-1'!$B$2:$Y$11,6,FALSE) -> #N/A | N6: =HLOOKUP($A6,'RTU 1-1'!$B$2:$Y$11,10,FALSE) -> NO | O6: =IF(N6="YES",600,"N/A") -> N/A | P6: =HLOOKUP($A6,'RTU 1-1'!$B$2:$Y$11,9,FALSE) -> #N/A
A7: VAV-1-2-1 | C7: =HLOOKUP(A7,'RTU 1-1'!$B$2:$Y$11,2,FALSE) -> 0 | L7: =HLOOKUP($A7,'RTU 1-1'!$B$2:$Y$11,7,FALSE) -> 0 | M7: =HLOOKUP($A7,'RTU 1-1'!$B$2:$Y$11,6,FALSE) -> 103.815 | N7: =HLOOKUP($A7,'RTU 1-1'!$B$2:$Y$11,10,FALSE) -> NO | O7: =IF(N7="YES",600,"N/A") -> N/A | P7: =HLOOKUP($A7,'RTU 1-1'!$B$2:$Y$11,9,FALSE) -> #N/A
A8: VAV-1-2-2 | C8: =HLOOKUP(A8,'RTU 1-1'!$B$2:$Y$11,2,FALSE) -> 0 | L8: =HLOOKUP($A8,'RTU 1-1'!$B$2:$Y$11,7,FALSE) -> 0 | M8: =HLOOKUP($A8,'RTU 1-1'!$B$2:$Y$11,6,FALSE) -> 47.085 | N8: =HLOOKUP($A8,'RTU 1-1'!$B$2:$Y$11,10,FALSE) -> NO | O8: =IF(N8="YES",600,"N/A") -> N/A | P8: =HLOOKUP($A8,'RTU 1-1'!$B$2:$Y$11,9,FALSE) -> #N/A
A9: VAV-1-2-3 | C9: =HLOOKUP(A9,'RTU 1-1'!$B$2:$Y$11,2,FALSE) -> 0 | L9: =HLOOKUP($A9,'RTU 1-1'!$B$2:$Y$11,7,FALSE) -> 0 | M9: =HLOOKUP($A9,'RTU 1-1'!$B$2:$Y$11,6,FALSE) -> 67.65 | N9: =HLOOKUP($A9,'RTU 1-1'!$B$2:$Y$11,10,FALSE) -> NO | O9: =IF(N9="YES",600,"N/A") -> N/A | P9: =HLOOKUP($A9,'RTU 1-1'!$B$2:$Y$11,9,FALSE) -> #N/A
A10: VAV-1-2-4 | C10: =HLOOKUP(A10,'RTU 1-1'!$B$2:$Y$11,2,FALSE) -> 0 | L10: =HLOOKUP($A10,'RTU 1-1'!$B$2:$Y$11,7,FALSE) -> 0 | M10: =HLOOKUP($A10,'RTU 1-1'!$B$2:$Y$11,6,FALSE) -> 97.665 | N10: =HLOOKUP($A10,'RTU 1-1'!$B$2:$Y$11,10,FALSE) -> NO | O10: =IF(N10="YES",600,"N/A") -> N/A | P10: =HLOOKUP($A10,'RTU 1-1'!$B$2:$Y$11,9,FALSE) -> #N/A
A11: VAV-1-2-5 | C11: =HLOOKUP(A11,'RTU 1-1'!$B$2:$Y$11,2,FALSE) -> 0 | L11: =HLOOKUP($A11,'RTU 1-1'!$B$2:$Y$11,7,FALSE) -> #N/A | M11: =HLOOKUP($A11,'RTU 1-1'!$B$2:$Y$11,6,FALSE) -> #N/A | N11: =HLOOKUP($A11,'RTU 1-1'!$B$2:$Y$11,10,FALSE) -> YES | O11: =IF(N11="YES",600,"N/A") -> 600 | P11: =HLOOKUP($A11,'RTU 1-1'!$B$2:$Y$11,9,FALSE) -> #N/A
A12: VAV-1-3-1 | C12: =HLOOKUP(A12,'RTU 1-1'!$B$2:$Y$11,2,FALSE) -> 0 | L12: =HLOOKUP($A12,'RTU 1-1'!$B$2:$Y$11,7,FALSE) -> #N/A | M12: =HLOOKUP($A12,'RTU 1-1'!$B$2:$Y$11,6,FALSE) -> #N/A | N12: =HLOOKUP($A12,'RTU 1-1'!$B$2:$Y$11,10,FALSE) -> NO | O12: =IF(N12="YES",600,"N/A") -> N/A | P12: =HLOOKUP($A12,'RTU 1-1'!$B$2:$Y$11,9,FALSE) -> #N/A
A13: VAV-1-3-2 | C13: =HLOOKUP(A13,'RTU 1-1'!$B$2:$Y$11,2,FALSE) -> 0 | L13: =HLOOKUP($A13,'RTU 1-1'!$B$2:$Y$11,7,FALSE) -> #N/A | M13: =HLOOKUP($A13,'RTU 1-1'!$B$2:$Y$11,6,FALSE) -> #N/A | N13: =HLOOKUP($A13,'RTU 1-1'!$B$2:$Y$11,10,FALSE) -> NO | O13: =IF(N13="YES",600,"N/A") -> N/A | P13: =HLOOKUP($A13,'RTU 1-1'!$B$2:$Y$11,9,FALSE) -> #N/A
A14: VAV-1-3-3 | C14: =HLOOKUP(A14,'RTU 1-1'!$B$2:$Y$11,2,FALSE) -> 0 | L14: =HLOOKUP($A14,'RTU 1-1'!$B$2:$Y$11,7,FALSE) -> #N/A | M14: =HLOOKUP($A14,'RTU 1-1'!$B$2:$Y$11,6,FALSE) -> #N/A | N14: =HLOOKUP($A14,'RTU 1-1'!$B$2:$Y$11,10,FALSE) -> NO | O14: =IF(N14="YES",600,"N/A") -> N/A | P14: =HLOOKUP($A14,'RTU 1-1'!$B$2:$Y$11,9,FALSE) -> #N/A
A15: VAV-1-3-4 | C15: =HLOOKUP(A15,'RTU 1-1'!$B$2:$Y$11,2,FALSE) -> 0 | L15: =HLOOKUP($A15,'RTU 1-1'!$B$2:$Y$11,7,FALSE) -> 0 | M15: =HLOOKUP($A15,'RTU 1-1'!$B$2:$Y$11,6,FALSE) -> 44.28 | N15: =HLOOKUP($A15,'RTU 1-1'!$B$2:$Y$11,10,FALSE) -> NO | O15: =IF(N15="YES",600,"N/A") -> N/A | P15: =HLOOKUP($A15,'RTU 1-1'!$B$2:$Y$11,9,FALSE) -> #N/A
A16: VAV-1-3-5 | C16: =HLOOKUP(A16,'RTU 1-1'!$B$2:$Y$11,2,FALSE) -> 0 | L16: =HLOOKUP($A16,'RTU 1-1'!$B$2:$Y$11,7,FALSE) -> #N/A | M16: =HLOOKUP($A16,'RTU 1-1'!$B$2:$Y$11,6,FALSE) -> #N/A | N16: =HLOOKUP($A16,'RTU 1-1'!$B$2:$Y$11,10,FALSE) -> NO | O16: =IF(N16="YES",600,"N/A") -> N/A | P16: =HLOOKUP($A16,'RTU 1-1'!$B$2:$Y$11,9,FALSE) -> #N/A
... A25: VAV-1-5-3 | C25: =HLOOKUP(A25,'RTU 1-1'!$B$2:$Y$11,2,FALSE) -> 0 | L25: =HLOOKUP($A25,'RTU 1-1'!$B$2:$Y$11,7,FALSE) -> 0 | M25: =HLOOKUP($A25,'RTU 1-1'!$B$2:$Y$11,6,FALSE) -> 27.225 | N25: =HLOOKUP($A25,'RTU 1-1'!$B$2:$Y$11,10,FALSE) -> NO | O25: =IF(N25="YES",600,"N/A") -> N/A | P25: =HLOOKUP($A25,'RTU 1-1'!$B$2:$Y$11,9,FALSE) -> #N/A
A26: 0 | C26: =HLOOKUP(A26,'RTU 1-1'!$B$2:$Y$11,2,FALSE) -> #N/A | L26: =HLOOKUP($A26,'RTU 1-1'!$B$2:$Y$11,7,FALSE) -> #N/A | M26: =HLOOKUP($A26,'RTU 1-1'!$B$2:$Y$11,6,FALSE) -> #N/A | N26: =HLOOKUP($A26,'RTU 1-1'!$B$2:$Y$11,10,FALSE) -> #N/A | O26: =IF(N26="YES",600,"N/A") -> #N/A | P26: =HLOOKUP($A26,'RTU 1-1'!$B$2:$Y$11,9,FALSE) -> #N/A
A27: 0 | C27: =HLOOKUP(A27,'RTU 1-1'!$B$2:$Y$11,2,FALSE) -> #N/A | L27: =HLOOKUP($A27,'RTU 1-1'!$B$2:$Y$11,7,FALSE) -> #N/A | M27: =HLOOKUP($A27,'RTU 1-1'!$B$2:$Y$11,6,FALSE) -> #N/A | N27: =HLOOKUP($A27,'RTU 1-1'!$B$2:$Y$11,10,FALSE) -> #N/A | O27: =IF(N27="YES",600,"N/A") -> #N/A | P27: =HLOOKUP($A27,'RTU 1-1'!$B$2:$Y$11,9,FALSE) -> #N/A
A28: {=TRANSPOSE('RTU 2-X'!B2:AG2)} -> VAV-2-1-1 | C28: =HLOOKUP(A28,'RTU 2-X'!$B$2:$AG$10,2,FALSE) -> 0 | L28: =HLOOKUP($A28,'RTU 2-X'!$B$2:$AG$10,7,FALSE) -> #N/A | M28: =HLOOKUP($A28,'RTU 2-X'!$B$2:$AG$10,6,FALSE) -> #N/A | N28: =HLOOKUP($A28,'RTU 2-X'!$B$2:$AG$11,10,FALSE) -> NO | O28: =IF(N28="YES",600,"N/A") -> N/A | P28: =HLOOKUP($A28,'RTU 2-X'!$B$2:$AG$11,9,FALSE) -> #N/A
A29: VAV-2-1-2 | C29: =HLOOKUP(A29,'RTU 2-X'!$B$2:$AG$10,2,FALSE) -> 0 | L29: =HLOOKUP($A29,'RTU 2-X'!$B$2:$AG$10,7,FALSE) -> 0 | M29: =HLOOKUP($A29,'RTU 2-X'!$B$2:$AG$10,6,FALSE) -> 15.75 | N29: =HLOOKUP($A29,'RTU 2-X'!$B$2:$AG$11,10,FALSE) -> NO | O29: =IF(N29="YES",600,"N/A") -> N/A | P29: =HLOOKUP($A29,'RTU 2-X'!$B$2:$AG$11,9,FALSE) -> #N/A
A30: VAV-2-1-3 | C30: =HLOOKUP(A30,'RTU 2-X'!$B$2:$AG$10,2,FALSE) -> 0 | L30: =HLOOKUP($A30,'RTU 2-X'!$B$2:$AG$10,7,FALSE) -> 0 | M30: =HLOOKUP($A30,'RTU 2-X'!$B$2:$AG$10,6,FALSE) -> 60 | N30: =HLOOKUP($A30,'RTU 2-X'!$B$2:$AG$11,10,FALSE) -> NO | O30: =IF(N30="YES",600,"N/A") -> N/A | P30: =HLOOKUP($A30,'RTU 2-X'!$B$2:$AG$11,9,FALSE) -> #N/A
A31: VAV-2-2-1 | C31: =HLOOKUP(A31,'RTU 2-X'!$B$2:$AG$10,2,FALSE) -> 0 | L31: =HLOOKUP($A31,'RTU 2-X'!$B$2:$AG$10,7,FALSE) -> 0 | M31: =HLOOKUP($A31,'RTU 2-X'!$B$2:$AG$10,6,FALSE) -> 44.52 | N31: =HLOOKUP($A31,'RTU 2-X'!$B$2:$AG$11,10,FALSE) -> NO | O31: =IF(N31="YES",600,"N/A") -> N/A | P31: =HLOOKUP($A31,'RTU 2-X'!$B$2:$AG$11,9,FALSE) -> #N/A
A32: VAV-2-2-2 | C32: =HLOOKUP(A32,'RTU 2-X'!$B$2:$AG$10,2,FALSE) -> 0 | L32: =HLOOKUP($A32,'RTU 2-X'!$B$2:$AG$10,7,FALSE) -> 0 | M32: =HLOOKUP($A32,'RTU 2-X'!$B$2:$AG$10,6,FALSE) -> 56.97 | N32: =HLOOKUP($A32,'RTU 2-X'!$B$2:$AG$11,10,FALSE) -> NO | O32: =IF(N32="YES",600,"N/A") -> N/A | P32: =HLOOKUP($A32,'RTU 2-X'!$B$2:$AG$11,9,FALSE) -> #N/A
A33: VAV-2-2-3 | C33: =HLOOKUP(A33,'RTU 2-X'!$B$2:$AG$10,2,FALSE) -> 0 | L33: =HLOOKUP($A33,'RTU 2-X'!$B$2:$AG$10,7,FALSE) -> 0 | M33: =HLOOKUP($A33,'RTU 2-X'!$B$2:$AG$10,6,FALSE) -> 57.405 | N33: =HLOOKUP($A33,'RTU 2-X'!$B$2:$AG$11,10,FALSE) -> NO | O33: =IF(N33="YES",600,"N/A") -> N/A | P33: =HLOOKUP($A33,'RTU 2-X'!$B$2:$AG$11,9,FALSE) -> #N/A
A34: VAV-2-2-4 | C34: =HLOOKUP(A34,'RTU 2-X'!$B$2:$AG$10,2,FALSE) -> 0 | L34: =HLOOKUP($A34,'RTU 2-X'!$B$2:$AG$10,7,FALSE) -> 0 | M34: =HLOOKUP($A34,'RTU 2-X'!$B$2:$AG$10,6,FALSE) -> 106.92 | N34: =HLOOKUP($A34,'RTU 2-X'!$B$2:$AG$11,10,FALSE) -> NO | O34: =IF(N34="YES",600,"N/A") -> N/A | P34: =HLOOKUP($A34,'RTU 2-X'!$B$2:$AG$11,9,FALSE) -> #N/A
A35: VAV-2-2-5 | C35: =HLOOKUP(A35,'RTU 2-X'!$B$2:$AG$10,2,FALSE) -> 0 | L35: =HLOOKUP($A35,'RTU 2-X'!$B$2:$AG$10,7,FALSE) -> #N/A | M35: =HLOOKUP($A35,'RTU 2-X'!$B$2:$AG$10,6,FALSE) -> #N/A | N35: =HLOOKUP($A35,'RTU 2-X'!$B$2:$AG$11,10,FALSE) -> YES | O35: =IF(N35="YES",600,"N/A") -> 600 | P35: =HLOOKUP($A35,'RTU 2-X'!$B$2:$AG$11,9,FALSE) -> #N/A
A36: VAV-2-2-6 | C36: =HLOOKUP(A36,'RTU 2-X'!$B$2:$AG$10,2,FALSE) -> 0 | L36: =HLOOKUP($A36,'RTU 2-X'!$B$2:$AG$10,7,FALSE) -> 0 | M36: =HLOOKUP($A36,'RTU 2-X'!$B$2:$AG$10,6,FALSE) -> 94.11 | N36: =HLOOKUP($A36,'RTU 2-X'!$B$2:$AG$11,10,FALSE) -> NO | O36: =IF(N36="YES",600,"N/A") -> N/A | P36: =HLOOKUP($A36,'RTU 2-X'!$B$2:$AG$11,9,FALSE) -> #N/A
A37: VAV-2-3-1 | C37: =HLOOKUP(A37,'RTU 2-X'!$B$2:$AG$10,2,FALSE) -> 0 | L37: =HLOOKUP($A37,'RTU 2-X'!$B$2:$AG$10,7,FALSE) -> 0 | M37: =HLOOKUP($A37,'RTU 2-X'!$B$2:$AG$10,6,FALSE) -> 61.5 | N37: =HLOOKUP($A37,'RTU 2-X'!$B$2:$AG$11,10,FALSE) -> NO | O37: =IF(N37="YES",600,"N/A") -> N/A | P37: =HLOOKUP($A37,'RTU 2-X'!$B$2:$AG$11,9,FALSE) -> #N/A
A38: VAV-2-3-2 | C38: =HLOOKUP(A38,'RTU 2-X'!$B$2:$AG$10,2,FALSE) -> 0 | L38: =HLOOKUP($A38,'RTU 2-X'!$B$2:$AG$10,7,FALSE) -> 0 | M38: =HLOOKUP($A38,'RTU 2-X'!$B$2:$AG$10,6,FALSE) -> 30 | N38: =HLOOKUP($A38,'RTU 2-X'!$B$2:$AG$11,10,FALSE) -> NO | O38: =IF(N38="YES",600,"N/A") -> N/A | P38: =HLOOKUP($A38,'RTU 2-X'!$B$2:$AG$11,9,FALSE) -> #N/A
A39: VAV-2-3-3 | C39: =HLOOKUP(A39,'RTU 2-X'!$B$2:$AG$10,2,FALSE) -> 0 | L39: =HLOOKUP($A39,'RTU 2-X'!$B$2:$AG$10,7,FALSE) -> 0 | M39: =HLOOKUP($A39,'RTU 2-X'!$B$2:$AG$10,6,FALSE) -> 15.12 | N39: =HLOOKUP($A39,'RTU 2-X'!$B$2:$AG$11,10,FALSE) -> NO | O39: =IF(N39="YES",600,"N/A") -> N/A | P39: =HLOOKUP($A39,'RTU 2-X'!$B$2:$AG$11,9,FALSE) -> #N/A
A40: VAV-2-3-4 | C40: =HLOOKUP(A40,'RTU 2-X'!$B$2:$AG$10,2,FALSE) -> 0 | L40: =HLOOKUP($A40,'RTU 2-X'!$B$2:$AG$10,7,FALSE) -> 0 | M40: =HLOOKUP($A40,'RTU 2-X'!$B$2:$AG$10,6,FALSE) -> 15.795 | N40: =HLOOKUP($A40,'RTU 2-X'!$B$2:$AG$11,10,FALSE) -> NO | O40: =IF(N40="YES",600,"N/A") -> N/A | P40: =HLOOKUP($A40,'RTU 2-X'!$B$2:$AG$11,9,FALSE) -> #N/A
... A59: VAV-2-5-7 | C59: =HLOOKUP(A59,'RTU 2-X'!$B$2:$AG$10,2,FALSE) -> 0 | L59: =HLOOKUP($A59,'RTU 2-X'!$B$2:$AG$10,7,FALSE) -> #N/A | M59: =HLOOKUP($A59,'RTU 2-X'!$B$2:$AG$10,6,FALSE) -> #N/A | N59: =HLOOKUP($A59,'RTU 2-X'!$B$2:$AG$11,10,FALSE) -> YES | O59: =IF(N59="YES",600,"N/A") -> 600 | P59: =HLOOKUP($A59,'RTU 2-X'!$B$2:$AG$11,9,FALSE) -> #N/A
C60: =HLOOKUP(A60,'AC-3'!$B$2:$S$10,2,FALSE) -> #N/A | L60: =HLOOKUP($A60,'AC-3'!$B$2:$S$10,6,FALSE) -> #N/A | M60: =HLOOKUP($A60,'AC-3'!$B$2:$S$10,7,FALSE) -> #N/A | N60: =HLOOKUP($A60,'AC-3'!$B$2:$S$11,10,FALSE) -> #N/A | O60: =IF(N60="YES",600,"N/A") -> #N/A | P60: =HLOOKUP($A60,'AC-3'!$B$2:$S$11,9,FALSE) -> #N/A
C61: =HLOOKUP(A61,'AC-3'!$B$2:$S$10,2,FALSE) -> #N/A | L61: =HLOOKUP($A61,'AC-3'!$B$2:$S$10,6,FALSE) -> #N/A | M61: =HLOOKUP($A61,'AC-3'!$B$2:$S$10,7,FALSE) -> #N/A | N61: =HLOOKUP($A61,'AC-3'!$B$2:$S$11,10,FALSE) -> #N/A | O61: =IF(N61="YES",600,"N/A") -> #N/A | P61: =HLOOKUP($A61,'AC-3'!$B$2:$S$11,9,FALSE) -> #N/A
C62: =HLOOKUP(A62,'AC-3'!$B$2:$S$10,2,FALSE) -> #N/A | L62: =HLOOKUP($A62,'AC-3'!$B$2:$S$10,6,FALSE) -> #N/A | M62: =HLOOKUP($A62,'AC-3'!$B$2:$S$10,7,FALSE) -> #N/A | N62: =HLOOKUP($A62,'AC-3'!$B$2:$S$11,10,FALSE) -> #N/A | O62: =IF(N62="YES",600,"N/A") -> #N/A | P62: =HLOOKUP($A62,'AC-3'!$B$2:$S$11,9,FALSE) -> #N/A
C63: =HLOOKUP(A63,'AC-3'!$B$2:$S$10,2,FALSE) -> #N/A | L63: =HLOOKUP($A63,'AC-3'!$B$2:$S$10,6,FALSE) -> #N/A | M63: =HLOOKUP($A63,'AC-3'!$B$2:$S$10,7,FALSE) -> #N/A | N63: =HLOOKUP($A63,'AC-3'!$B$2:$S$11,10,FALSE) -> #N/A | O63: =IF(N63="YES",600,"N/A") -> #N/A | P63: =HLOOKUP($A63,'AC-3'!$B$2:$S$11,9,FALSE) -> #N/A
C64: =HLOOKUP(A64,'AC-3'!$B$2:$S$10,2,FALSE) -> #N/A | L64: =HLOOKUP($A64,'AC-3'!$B$2:$S$10,6,FALSE) -> #N/A | M64: =HLOOKUP($A64,'AC-3'!$B$2:$S$10,7,FALSE) -> #N/A | N64: =HLOOKUP($A64,'AC-3'!$B$2:$S$11,10,FALSE) -> #N/A | O64: =IF(N64="YES",600,"N/A") -> #N/A | P64: =HLOOKUP($A64,'AC-3'!$B$2:$S$11,9,FALSE) -> #N/A
C65: =HLOOKUP(A65,'AC-3'!$B$2:$S$10,2,FALSE) -> #N/A | L65: =HLOOKUP($A65,'AC-3'!$B$2:$S$10,6,FALSE) -> #N/A | M65: =HLOOKUP($A65,'AC-3'!$B$2:$S$10,7,FALSE) -> #N/A | N65: =HLOOKUP($A65,'AC-3'!$B$2:$S$11,10,FALSE) -> #N/A | O65: =IF(N65="YES",600,"N/A") -> #N/A | P65: =HLOOKUP($A65,'AC-3'!$B$2:$S$11,9,FALSE) -> #N/A
C66: =HLOOKUP(A66,'AC-3'!$B$2:$S$10,2,FALSE) -> #N/A | L66: =HLOOKUP($A66,'AC-3'!$B$2:$S$10,6,FALSE) -> #N/A | M66: =HLOOKUP($A66,'AC-3'!$B$2:$S$10,7,FALSE) -> #N/A | N66: =HLOOKUP($A66,'AC-3'!$B$2:$S$11,10,FALSE) -> #N/A | O66: =IF(N66="YES",600,"N/A") -> #N/A | P66: =HLOOKUP($A66,'AC-3'!$B$2:$S$11,9,FALSE) -> #N/A
...
